<?xml version="1.0"?>
<robot name="manipulator_description" xmlns:xacro="http://www.ros.org/wiki/xacro">
   
  <!-- Include materials -->
	<!--xacro:include filename="$(find manipulator_description)/urdf/materials.xacro" /-->



<!-- base link-->
    <link name="base_link">
        
<inertial>
            <origin xyz="-3.10150703372852E-09 7.69217301046195E-10 0.0392285802246154" rpy="0 0 0" />
            <mass value="1000" />
            <inertia ixx="100.0" ixy="0.0" ixz="0.0" iyy="100.0" iyz="0.0" izz="100.0" />
        </inertial>

        <visual>
            <origin xyz="0 0 0" rpy="0 0 0" />
            <geometry>
                <mesh filename="package://manipulator_description/meshes/base_link.STL" />
            </geometry>
            <material name="black" />
        </visual>
        <collision>
            <origin xyz="0 0 0" rpy="0 0 0" />
            <geometry>
                <mesh filename="package://manipulator_description/meshes/base_link.STL" />
            </geometry>
        </collision>
    </link>



    <link name="Link_1">
        
<inertial>
            <origin xyz="-3.48593329235086E-07 0.0109897641420375 -0.00482036436458533" rpy="0 0 0" />
            <!--<mass value="15.4132239446567" />-->
            <mass value="1" />
            <!--<inertia ixx="0.135780244533804" ixy="-3.53337665158229E-07" ixz="7.18129805236185E-08" iyy="0.12985561288227" iyz="-0.000816179282847615" izz="0.101703255595037" />-->
            <inertia ixx="100.0" ixy="0.0" ixz="0.0" iyy="100.0" iyz="0.0" izz="100.0" />-->
        </inertial>

        <visual>
            <origin xyz="0 0 0" rpy="0 0 0" />
            <geometry>
                <mesh filename="package://manipulator_description/meshes/Link_1.STL" />
            </geometry>
            <material name="dark_grey" />
        </visual>
        <collision>
            <origin xyz="0 0 0" rpy="0 0 0" />
            <geometry>
                <mesh filename="package://manipulator_description/meshes/Link_1.STL" />
            </geometry>
        </collision>
    </link>
    <joint name="joint_1" type="continuous">
        <origin xyz="0 0 0.2" rpy="0 0 0" />
        <parent link="base_link" />
        <child link="Link_1" />
        <axis xyz="0 0 -1" />
        <limit lower="0" upper="0" effort="1000" velocity="1.5708" />
    </joint>
    <link name="Link_2">
        
<inertial>
            <origin xyz="4.64288584211257E-08 -0.450307572690538 0.207197326540885" rpy="0 0 0" />
            <!--<mass value="12.4980114959896" />-->
            <mass value="1" />
            <!--<inertia ixx="0.638712959689058" ixy="-9.58476459860646E-09" ixz="1.91592302802584E-08" iyy="0.0600554822378791" iyz="0.00017322666699373" izz="0.633088322617104" />-->
            <inertia ixx="100.0" ixy="0.0" ixz="0.0" iyy="100.0" iyz="0.0" izz="100.0" />
        </inertial>

        <visual>
            <origin xyz="0 0 0" rpy="0 0 0" />
            <geometry>
                <mesh filename="package://manipulator_description/meshes/Link_2.STL" />
            </geometry>
            <material name="light_grey" />
        </visual>
        <collision>
            <origin xyz="0 0 0" rpy="0 0 0" />
            <geometry>
                <mesh filename="package://manipulator_description/meshes/Link_2.STL" />
            </geometry>
        </collision>
    </link>
    <joint name="joint_2" type="revolute">
        <origin xyz="0 0 0" rpy="-1.5708 0 0" />
        <parent link="Link_1" />
        <child link="Link_2" />
        <axis xyz="0 0 -1" />
        <limit lower="-0.6236" upper="1.96" effort="1000" velocity="1.5708" />
    </joint>
    <link name="Link_3">
        
<inertial>
            <origin xyz="-0.000152239281300259 -6.44384849479815E-08 -0.151975016298213" rpy="0 0 0" />
            <!--<mass value="0.845202115671464" />-->
            <mass value="1" />
            <!--<inertia ixx="0.002061765900448" ixy="3.53941839411554E-09" ixz="-7.79445575850648E-07" iyy="0.00310222379140893" iyz="-6.81293975922967E-09" izz="0.00320233963547074" />-->
            <inertia ixx="40.0" ixy="0.0" ixz="0.0" iyy="40.0" iyz="0.0" izz="40.0" />
        </inertial>

        <visual>
            <origin xyz="0 0 0" rpy="0 0 0" />
            <geometry>
                <mesh filename="package://manipulator_description/meshes/Link_3.STL" />
            </geometry>
            <material name="dark_grey" />
        </visual>
        <collision>
            <origin xyz="0 0 0" rpy="0 0 0" />
            <geometry>
                <mesh filename="package://manipulator_description/meshes/Link_3.STL" />
            </geometry>
        </collision>
    </link>
    <joint name="joint_3" type="revolute">
        <origin xyz="0 -1 0.208" rpy="0 0 1.5708" />
        <parent link="Link_2" />
        <child link="Link_3" />
        <axis xyz="0 0 1" />
        <limit lower="-2.9" upper="2.9" effort="848" velocity="1.9477" />
    </joint>
    <link name="Link_4">
        
<inertial>
            <origin xyz="-0.00185023742496417 -0.00085145709068035 0.427869656938719" rpy="0 0 0" />
            <!--<mass value="6.06653386468215" />-->
            <mass value="1" />
            <!--<inertia ixx="0.139569161237106" ixy="-7.31848679471303E-05" ixz="0.00204904149975265" iyy="0.141430543001644" iyz="0.000865064721387192" izz="0.0145263272967812" />-->
            <inertia ixx="40.0" ixy="0.0" ixz="0.0" iyy="40.0" iyz="0.0" izz="40.0" />
        </inertial>

        <visual>
            <origin xyz="0 0 0" rpy="0 0 0" />
            <geometry>
                <mesh filename="package://manipulator_description/meshes/Link_4.STL" />
            </geometry>
            <material name="light_grey" />
        </visual>
        <collision>
            <origin xyz="0 0 0" rpy="0 0 0" />
            <geometry>
                <mesh filename="package://manipulator_description/meshes/Link_4.STL" />
            </geometry>
        </collision>
    </link>
    <joint name="joint_4" type="revolute">
        <origin xyz="-0.001 0 -0.169" rpy="0.23843 1.5708 -2.9032" />
        <parent link="Link_3" />
        <child link="Link_4" />
        <axis xyz="0 0 -1" />
        <limit lower="-0.6" upper="0.6" effort="284" velocity="2.6179" />
    </joint>
    <link name="Link_5">
        
<inertial>
            <origin xyz="-0.00548935425108261 -2.0681120402842E-05 -0.018180509143497" rpy="0 0 0" />
            <!--<mass value="1.02684751175617" />-->
            <mass value="0.1" />            
            <!--<inertia ixx="0.00276845094372366" ixy="8.70701635096604E-10" ixz="1.49334189715339E-05" iyy="0.0026939467219375" iyz="-1.24095535692237E-07" izz="0.00113622032677912" />-->
            <inertia ixx="10.0" ixy="0.0" ixz="0.0" iyy="10.0" iyz="0.0" izz="10.0" />
        </inertial>

        <visual>
            <origin xyz="0 0 0" rpy="0 0 0" />
            <geometry>
                <mesh filename="package://manipulator_description/meshes/Link_5.STL" />
            </geometry>
            <material name="light_grey" />
        </visual>
        <collision>
            <origin xyz="0 0 0" rpy="0 0 0" />
            <geometry>
                <mesh filename="package://manipulator_description/meshes/Link_5.STL" />
            </geometry>
        </collision>
    </link>
    <joint name="joint_5" type="revolute">
        <origin xyz="0 0 0.77" rpy="3.1326 0 -3.1299" />
        <parent link="Link_4" />
        <child link="Link_5" />
        <axis xyz="1 0 0" />
        <limit lower="-2" upper="2" effort="80" velocity="3.665" />
    </joint>
    <link name="Link_6">
        
<inertial>
            <origin xyz="-0.00240134732899384 -0.000145858477892405 -0.169290413904326" rpy="0 0 0" />
            <mass value="0.459681563463666" />
            <!--<inertia ixx="0.000833463252802299" ixy="3.76538081686424E-11" ixz="1.61931097210786E-05" iyy="0.000820331788867551" iyz="3.89355608944618E-08" izz="0.000412879899555727" />-->
            <inertia ixx="1.0" ixy="0.0" ixz="0.0" iyy="1.0" iyz="0.0" izz="1.0" />
        </inertial>

        <visual>
            <origin xyz="0 0 0" rpy="0 0 0" />
            <geometry>
                <mesh filename="package://manipulator_description/meshes/Link_6.STL" />
            </geometry>
            <material name="light_grey" />
        </visual>
        <collision>
            <origin xyz="0 0 0" rpy="0 0 0" />
            <geometry>
                <mesh filename="package://manipulator_description/meshes/Link_6.STL" />
            </geometry>
        </collision>
    </link>
    <joint name="joint_6" type="revolute">
        <origin xyz="-0.0045 -1.7975E-05 -0.3655" rpy="3.1416 0 1.6078" />
        <parent link="Link_5" />
        <child link="Link_6" />
        <axis xyz="0 0 1" />
        <limit lower="-3.1415" upper="3.1415" effort="86" velocity="3.665" />
    </joint>
    <link name="push_Link">
        
<inertial>
            <origin xyz="0.0204799322370691 -0.000588633057326891 0.129588528024653" rpy="0 0 0" />
            <mass value="0.0363787354805148" />
            <!--<inertia ixx="1.21298771021865E-05" ixy="3.81546278402822E-07" ixz="7.63042085638405E-08" iyy="2.45804757674032E-05" iyz="-4.82527858335196E-09" izz="1.81356034678196E-05" />-->
            <inertia ixx="1.0" ixy="0.0" ixz="0.0" iyy="1.0" iyz="0.0" izz="1.0" />
        </inertial>

        <visual>
            <origin xyz="0 0 0" rpy="0 0 0" />
            <geometry>
                <mesh filename="package://manipulator_description/meshes/push_Link.STL" />
            </geometry>
            <material name="light_grey" />
        </visual>
        <collision>
            <origin xyz="0 0 0" rpy="0 0 0" />
            <geometry>
                <mesh filename="package://manipulator_description/meshes/push_Link.STL" />
            </geometry>
        </collision>
    </link>
    <joint name="push_joint" type="prismatic">
        <origin xyz="-0.019208 0 -0.22247" rpy="0 0 -1.5454" />
        <parent link="Link_6" />
        <child link="push_Link" />
        <axis xyz="0 0 -1" />
        <limit lower="-0.1" upper="0.0" effort="100" velocity="1" />
        <dynamics damping="50" friction="1" />
        <safety_controller soft_upper="0" soft_lower="-0.15" k_position="20" k_velocity="20" />
    </joint>
    <!-- Transmissions for ROS-Control -->
   
    <transmission name="trans_joint_1">
        <type>transmission_interface/SimpleTransmission</type>
        <joint name="joint_1">
            <hardwareInterface>hardware_interface/VelocityJointInterface</hardwareInterface>
        </joint>
        <actuator name="joint_1_motor">
            <hardwareInterface>hardware_interface/VelocityJointInterface</hardwareInterface>
            <mechanicalReduction>1</mechanicalReduction>
        </actuator>
    </transmission>
    <transmission name="trans_joint_2">
        <type>transmission_interface/SimpleTransmission</type>
        <joint name="joint_2">
            <hardwareInterface>hardware_interface/VelocityJointInterface</hardwareInterface>
        </joint>
        <actuator name="joint_2_motor">
            <hardwareInterface>hardware_interface/VelocityJointInterface</hardwareInterface>
            <mechanicalReduction>1</mechanicalReduction>
        </actuator>
    </transmission>
    <transmission name="trans_joint_3">
        <type>transmission_interface/SimpleTransmission</type>
        <joint name="joint_3">
            <hardwareInterface>hardware_interface/VelocityJointInterface</hardwareInterface>
        </joint>
        <actuator name="joint_3_motor">
            <hardwareInterface>hardware_interface/VelocityJointInterface</hardwareInterface>
            <mechanicalReduction>1</mechanicalReduction>
        </actuator>
    </transmission>
    <transmission name="trans_joint_4">
        <type>transmission_interface/SimpleTransmission</type>
        <joint name="joint_4">
            <hardwareInterface>hardware_interface/VelocityJointInterface</hardwareInterface>
        </joint>
        <actuator name="joint_4_motor">
            <hardwareInterface>hardware_interface/VelocityJointInterface</hardwareInterface>
            <mechanicalReduction>1</mechanicalReduction>
        </actuator>
    </transmission>
    <transmission name="trans_joint_5">
        <type>transmission_interface/SimpleTransmission</type>
        <joint name="joint_5">
            <hardwareInterface>hardware_interface/VelocityJointInterface</hardwareInterface>
        </joint>
        <actuator name="joint_5_motor">
            <hardwareInterface>hardware_interface/VelocityJointInterface</hardwareInterface>
            <mechanicalReduction>1</mechanicalReduction>
        </actuator>
    </transmission>
    <transmission name="trans_joint_6">
        <type>transmission_interface/SimpleTransmission</type>
        <joint name="joint_6">
            <hardwareInterface>hardware_interface/VelocityJointInterface</hardwareInterface>
        </joint>
        <actuator name="joint_6_motor">
            <hardwareInterface>hardware_interface/VelocityJointInterface</hardwareInterface>
            <mechanicalReduction>1</mechanicalReduction>
        </actuator>
    </transmission>
    <transmission name="trans_push_joint">
        <type>transmission_interface/SimpleTransmission</type>
        <joint name="push_joint">
            <hardwareInterface>hardware_interface/VelocityJointInterface</hardwareInterface>
        </joint>
        <actuator name="push_joint_motor">
            <hardwareInterface>hardware_interface/VelocityJointInterface</hardwareInterface>
            <mechanicalReduction>1</mechanicalReduction>
        </actuator>
    </transmission>


 <!-- ros_control plugin -->
    <gazebo>
        <plugin name="gazebo_ros_control" filename="libgazebo_ros_control.so">
            <robotNamespace>/manipulator_description</robotNamespace>
            <robotSimType>gazebo_ros_control/DefaultRobotHWSim</robotSimType>
            <legacyModeNS>true</legacyModeNS>
        </plugin>
    </gazebo>


  <!-- Gazebo Link properties 
  https://github.com/osrf/gazebo/blob/master/media/materials/scripts/gazebo.material
      -->
  <gazebo reference="base_link">
    <material>Gazebo/Black</material>
    <!--turnGravityOff>false</turnGravityOff-->
  </gazebo>

  <gazebo reference="Link_1">
    <material>Gazebo/DarkGrey</material>
    <!--turnGravityOff>false</turnGravityOff-->
  </gazebo>

  <gazebo reference="Link_2">
    <material>Gazebo/Grey</material>
    <!--turnGravityOff>false</turnGravityOff-->
  </gazebo>

  <gazebo reference="Link_3">
    <material>Gazebo/DarkGrey</material>
    <!--turnGravityOff>false</turnGravityOff-->
  </gazebo>

  <gazebo reference="Link_4">
    <material>Gazebo/Grey</material>
    <!--turnGravityOff>false</turnGravityOff-->
  </gazebo>

  <gazebo reference="Link_5">
    <material>Gazebo/Grey</material>
    <!--turnGravityOff>false</turnGravityOff-->
  </gazebo>

  <gazebo reference="Link_6">
    <material>Gazebo/Grey</material>
    <!--turnGravityOff>false</turnGravityOff-->
  </gazebo>

  <gazebo reference="push_Link">
    <material>Gazebo/Grey</material>
    <!--turnGravityOff>false</turnGravityOff-->
  </gazebo>
</robot>
