<?xml version="1.0" encoding="utf-8"?>
<!-- This URDF was automatically created by SolidWorks to URDF Exporter! Originally created by Stephen Brawner (brawner@gmail.com) 
     Commit Version: 1.5.1-0-g916b5db  Build Version: 1.5.7152.31018
     For more information, please see http://wiki.ros.org/sw_urdf_exporter -->
<robot
  name="agv">
  <link
    name="base_footprint">
    <inertial>
      <origin
        xyz="3.46944695195361E-18 -5.55111512312578E-17 2.0000000000131E-05"
        rpy="0 0 0" />
      <mass
        value="2.01061929829948E-06" />
      <inertia
        ixx="8.04274527577102E-12"
        ixy="1.74616350177578E-55"
        ixz="3.13801719793953E-41"
        iyy="8.04274527577102E-12"
        iyz="-3.1083661313164E-46"
        izz="1.60849543863958E-11" />
    </inertial>
    <visual>
      <origin
        xyz="0 0 0"
        rpy="0 0 0" />
      <geometry>
        <mesh
          filename="package://agv_description/meshes/base_footprint.STL" />
      </geometry>
      <material
        name="">
        <color
          rgba="0.792156862745098 0.819607843137255 0.933333333333333 1" />
      </material>
    </visual>
    <collision>
      <origin
        xyz="0 0 0"
        rpy="0 0 0" />
      <geometry>
        <mesh
          filename="package://agv_description/meshes/base_footprint.STL" />
      </geometry>
    </collision>
  </link>
  <link
    name="base_Link">
    <inertial>
      <origin
        xyz="5.55111512312578E-17 -5.55111512312578E-17 0.125713618058247"
        rpy="0 0 0" />
      <mass
        value="728.097611322316" />
      <inertia
        ixx="133.566305698896"
        ixy="-5.4752209710518E-15"
        ixz="1.84390819133475E-16"
        iyy="242.974613570221"
        iyz="5.8190149305217E-16"
        izz="368.924129651498" />
    </inertial>
    <visual>
      <origin
        xyz="0 0 0"
        rpy="0 0 0" />
      <geometry>
        <mesh
          filename="package://agv_description/meshes/base_Link.STL" />
      </geometry>
      <material
        name="">
        <color
          rgba="1 1 1 1" />
      </material>
    </visual>
    <collision>
      <origin
        xyz="0 0 0"
        rpy="0 0 0" />
      <geometry>
        <mesh
          filename="package://agv_description/meshes/base_Link.STL" />
      </geometry>
    </collision>
  </link>
  <joint
    name="base_footprint_joint"
    type="fixed">
    <origin
      xyz="0 0 4E-05"
      rpy="0 0 0" />
    <parent
      link="base_footprint" />
    <child
      link="base_Link" />
    <axis
      xyz="0 0 0" />
  </joint>
  <link
    name="fl_Link">
    <inertial>
      <origin
        xyz="0 -2.22044604925031E-16 0.035"
        rpy="0 0 0" />
      <mass
        value="2.02796060125243" />
      <inertia
        ixx="0.00615294550222383"
        ixy="-2.34337466040914E-37"
        ixz="-3.67174469838234E-35"
        iyy="0.00615294550222383"
        iyz="-1.24830192880275E-35"
        izz="0.0106948140752879" />
    </inertial>
    <visual>
      <origin
        xyz="0 0 0"
        rpy="0 0 0" />
      <geometry>
        <mesh
          filename="package://agv_description/meshes/fl_Link.STL" />
      </geometry>
      <material
        name="">
        <color
          rgba="1 1 1 1" />
      </material>
    </visual>
    <collision>
      <origin
        xyz="0 0 0"
        rpy="0 0 0" />
      <geometry>
        <mesh
          filename="package://agv_description/meshes/fl_Link.STL" />
      </geometry>
    </collision>
  </link>
  <joint
    name="fl_joint"
    type="continuous">
    <origin
      xyz="0.6 0.68 0.09"
      rpy="-1.5708 0 0" />
    <parent
      link="base_Link" />
    <child
      link="fl_Link" />
    <axis
      xyz="0 0 1" />
  </joint>
  <link
    name="bl_Link">
    <inertial>
      <origin
        xyz="1.11022302462516E-16 0 0.0349886144674467"
        rpy="0 0 0" />
      <mass
        value="2.0286827045136" />
      <inertia
        ixx="0.00615398036846577"
        ixy="2.01225942475967E-34"
        ixz="9.73822666280366E-23"
        iyy="0.00615398036846577"
        iyz="-1.31655367292096E-33"
        izz="0.0106953992824643" />
    </inertial>
    <visual>
      <origin
        xyz="0 0 0"
        rpy="0 0 0" />
      <geometry>
        <mesh
          filename="package://agv_description/meshes/bl_Link.STL" />
      </geometry>
      <material
        name="">
        <color
          rgba="1 1 1 1" />
      </material>
    </visual>
    <collision>
      <origin
        xyz="0 0 0"
        rpy="0 0 0" />
      <geometry>
        <mesh
          filename="package://agv_description/meshes/bl_Link.STL" />
      </geometry>
    </collision>
  </link>
  <joint
    name="bl_joint"
    type="continuous">
    <origin
      xyz="-0.6 0.68 0.0900000000000001"
      rpy="-1.5707963267949 0 0" />
    <parent
      link="base_Link" />
    <child
      link="bl_Link" />
    <axis
      xyz="0 0 1" />
  </joint>
  <link
    name="fr_Link">
    <inertial>
      <origin
        xyz="0 2.22044604925031E-16 0.0350501592853405"
        rpy="0 0 0" />
      <mass
        value="2.03116301113069" />
      <inertia
        ixx="0.00616813439647654"
        ixy="-2.49506093056538E-34"
        ixz="-1.10979702273246E-19"
        iyy="0.00616813439647653"
        iyz="1.86315854605333E-33"
        izz="0.0107186859543853" />
    </inertial>
    <visual>
      <origin
        xyz="0 0 0"
        rpy="0 0 0" />
      <geometry>
        <mesh
          filename="package://agv_description/meshes/fr_Link.STL" />
      </geometry>
      <material
        name="">
        <color
          rgba="1 1 1 1" />
      </material>
    </visual>
    <collision>
      <origin
        xyz="0 0 0"
        rpy="0 0 0" />
      <geometry>
        <mesh
          filename="package://agv_description/meshes/fr_Link.STL" />
      </geometry>
    </collision>
  </link>
  <joint
    name="fr_joint"
    type="continuous">
    <origin
      xyz="0.6 -0.68 0.0900000000000001"
      rpy="1.5707963267949 0 0" />
    <parent
      link="base_Link" />
    <child
      link="fr_Link" />
    <axis
      xyz="0 0 1" />
  </joint>
  <link
    name="br_Link">
    <inertial>
      <origin
        xyz="0 0 0.0349611985496496"
        rpy="0 0 0" />
      <mass
        value="2.03044090786952" />
      <inertia
        ixx="0.00616710132063279"
        ixy="-1.22133482371899E-36"
        ixz="1.10920318812234E-19"
        iyy="0.00616710132063279"
        iyz="-1.26745985148929E-35"
        izz="0.010718100747209" />
    </inertial>
    <visual>
      <origin
        xyz="0 0 0"
        rpy="0 0 0" />
      <geometry>
        <mesh
          filename="package://agv_description/meshes/br_Link.STL" />
      </geometry>
      <material
        name="">
        <color
          rgba="1 1 1 1" />
      </material>
    </visual>
    <collision>
      <origin
        xyz="0 0 0"
        rpy="0 0 0" />
      <geometry>
        <mesh
          filename="package://agv_description/meshes/br_Link.STL" />
      </geometry>
    </collision>
  </link>
  <joint
    name="br_joint"
    type="continuous">
    <origin
      xyz="-0.6 -0.68 0.0899999999999994"
      rpy="1.5707963267949 0 0" />
    <parent
      link="base_Link" />
    <child
      link="br_Link" />
    <axis
      xyz="0 0 1" />
  </joint>
</robot>
